INFO 2023-08-22 17:16:57,362 [main.py:captureLog:68] Connecting to device xe1
INFO 2023-08-22 17:16:59,448 [main.py:captureLogX:45] ---getting capture logging from device xe1---
INFO 2023-08-22 17:16:59,716 [main.py:captureLogX:51] xe1_22-08-23_17_16_59.txt
INFO 2023-08-22 17:16:59,718 [main.py:captureLog:77] Get Logging Device - execution completed successfully.
INFO 2023-08-22 17:22:58,646 [main.py:captureLog:68] Connecting to device xe1
INFO 2023-08-22 17:23:00,747 [main.py:captureLogX:45] ---getting capture logging from device xe1---
INFO 2023-08-22 17:23:00,979 [main.py:captureLogX:51] xe1_22-08-23_17_23_00.txt
INFO 2023-08-22 17:23:00,981 [main.py:captureLog:77] Get Logging Device - execution completed successfully.
INFO 2023-08-29 11:31:46,495 [main.py:captureLog:85] Connecting to device xe1
ERROR 2023-08-29 11:32:00,602 [main.py:captureLogX:54] Connection attempt 1/3 failed for xe1 (198.18.0.121): failed to connect to xe1
Failed while bringing device to "any" state
INFO 2023-08-29 11:32:00,604 [main.py:captureLogX:55] Retrying in 2 seconds...
ERROR 2023-08-29 11:32:16,727 [main.py:captureLogX:54] Connection attempt 2/3 failed for xe1 (198.18.0.121): failed to connect to xe1
Failed while bringing device to "any" state
INFO 2023-08-29 11:32:16,729 [main.py:captureLogX:55] Retrying in 2 seconds...
ERROR 2023-08-29 11:32:32,815 [main.py:captureLogX:58] Failed to establish connection to xe1 (198.18.0.121) after 3 attempts.
INFO 2023-08-29 11:32:32,819 [main.py:captureLogX:62] ---getting capture logging from device xe1---
ERROR 2023-08-29 11:32:46,899 [main.py:captureLogX:76] Error connecting to device xe1: failed to connect to xe1
Failed while bringing device to "any" state
INFO 2023-08-29 11:32:46,901 [main.py:captureLog:94] Get Logging Device - execution completed successfully.
